<?xml version="1.0" encoding="UTF-8"?>
<testng-results skipped="0" failed="7" total="27" passed="20">
  <reporter-output>
    <line>
      <![CDATA[[Info] : Test Case is Skiped ]]>
    </line>
  </reporter-output>
  <suite name="SuiteNameHere" duration-ms="95" started-at="2020-04-01T13:16:01Z" finished-at="2020-04-01T13:16:01Z">
    <groups>
    </groups>
    <test name="Tests" duration-ms="95" started-at="2020-04-01T13:16:01Z" finished-at="2020-04-01T13:16:01Z">
      <class name="Demo.TestClass3">
        <test-method status="PASS" signature="class2_Method5()[pri:0, instance:Demo.TestClass3@4f933fd1]" name="class2_Method5" duration-ms="1" started-at="2020-04-01T18:46:01Z" finished-at="2020-04-01T18:46:01Z">
          <reporter-output>
          </reporter-output>
        </test-method> <!-- class2_Method5 -->
        <test-method status="PASS" signature="class2_Method1()[pri:1, instance:Demo.TestClass3@4f933fd1]" name="class2_Method1" duration-ms="1" started-at="2020-04-01T18:46:01Z" finished-at="2020-04-01T18:46:01Z">
          <reporter-output>
          </reporter-output>
        </test-method> <!-- class2_Method1 -->
        <test-method status="FAIL" signature="class2_Method2()[pri:2, instance:Demo.TestClass3@4f933fd1]" name="class2_Method2" duration-ms="2" started-at="2020-04-01T18:46:01Z" finished-at="2020-04-01T18:46:01Z">
          <exception class="java.lang.AssertionError">
            <message>
              <![CDATA[expected [true] but found [false]]]>
            </message>
            <full-stacktrace>
              <![CDATA[java.lang.AssertionError: expected [true] but found [false]
	at org.testng.Assert.fail(Assert.java:94)
	at org.testng.Assert.failNotEquals(Assert.java:513)
	at org.testng.Assert.assertTrue(Assert.java:42)
	at org.testng.Assert.assertTrue(Assert.java:52)
	at Demo.TestClass3.class2_Method2(TestClass3.java:16)
	at sun.reflect.NativeMethodAccessorImpl.invoke0(Native Method)
	at sun.reflect.NativeMethodAccessorImpl.invoke(NativeMethodAccessorImpl.java:62)
	at sun.reflect.DelegatingMethodAccessorImpl.invoke(DelegatingMethodAccessorImpl.java:43)
	at java.lang.reflect.Method.invoke(Method.java:498)
	at org.testng.internal.MethodInvocationHelper.invokeMethod(MethodInvocationHelper.java:86)
	at org.testng.internal.Invoker.invokeMethod(Invoker.java:643)
	at org.testng.internal.Invoker.invokeTestMethod(Invoker.java:820)
	at org.testng.internal.Invoker.invokeTestMethods(Invoker.java:1128)
	at org.testng.internal.TestMethodWorker.invokeTestMethods(TestMethodWorker.java:129)
	at org.testng.internal.TestMethodWorker.run(TestMethodWorker.java:112)
	at org.testng.TestRunner.privateRun(TestRunner.java:782)
	at org.testng.TestRunner.run(TestRunner.java:632)
	at org.testng.SuiteRunner.runTest(SuiteRunner.java:366)
	at org.testng.SuiteRunner.runSequentially(SuiteRunner.java:361)
	at org.testng.SuiteRunner.privateRun(SuiteRunner.java:319)
	at org.testng.SuiteRunner.run(SuiteRunner.java:268)
	at org.testng.SuiteRunnerWorker.runSuite(SuiteRunnerWorker.java:52)
	at org.testng.SuiteRunnerWorker.run(SuiteRunnerWorker.java:86)
	at org.testng.TestNG.runSuitesSequentially(TestNG.java:1244)
	at org.testng.TestNG.runSuitesLocally(TestNG.java:1169)
	at org.testng.TestNG.run(TestNG.java:1064)
	at org.testng.remote.AbstractRemoteTestNG.run(AbstractRemoteTestNG.java:115)
	at org.testng.remote.RemoteTestNG.initAndRun(RemoteTestNG.java:251)
	at org.testng.remote.RemoteTestNG.main(RemoteTestNG.java:77)
]]>
            </full-stacktrace>
          </exception> <!-- java.lang.AssertionError -->
          <reporter-output>
          </reporter-output>
        </test-method> <!-- class2_Method2 -->
        <test-method status="PASS" signature="class2_Method3()[pri:3, instance:Demo.TestClass3@4f933fd1]" name="class2_Method3" duration-ms="1" started-at="2020-04-01T18:46:01Z" finished-at="2020-04-01T18:46:01Z">
          <reporter-output>
          </reporter-output>
        </test-method> <!-- class2_Method3 -->
        <test-method status="FAIL" signature="class2_Method4()[pri:4, instance:Demo.TestClass3@4f933fd1]" name="class2_Method4" duration-ms="1" started-at="2020-04-01T18:46:01Z" finished-at="2020-04-01T18:46:01Z">
          <exception class="java.lang.AssertionError">
            <message>
              <![CDATA[expected [true] but found [false]]]>
            </message>
            <full-stacktrace>
              <![CDATA[java.lang.AssertionError: expected [true] but found [false]
	at org.testng.Assert.fail(Assert.java:94)
	at org.testng.Assert.failNotEquals(Assert.java:513)
	at org.testng.Assert.assertTrue(Assert.java:42)
	at org.testng.Assert.assertTrue(Assert.java:52)
	at Demo.TestClass3.class2_Method4(TestClass3.java:28)
	at sun.reflect.NativeMethodAccessorImpl.invoke0(Native Method)
	at sun.reflect.NativeMethodAccessorImpl.invoke(NativeMethodAccessorImpl.java:62)
	at sun.reflect.DelegatingMethodAccessorImpl.invoke(DelegatingMethodAccessorImpl.java:43)
	at java.lang.reflect.Method.invoke(Method.java:498)
	at org.testng.internal.MethodInvocationHelper.invokeMethod(MethodInvocationHelper.java:86)
	at org.testng.internal.Invoker.invokeMethod(Invoker.java:643)
	at org.testng.internal.Invoker.invokeTestMethod(Invoker.java:820)
	at org.testng.internal.Invoker.invokeTestMethods(Invoker.java:1128)
	at org.testng.internal.TestMethodWorker.invokeTestMethods(TestMethodWorker.java:129)
	at org.testng.internal.TestMethodWorker.run(TestMethodWorker.java:112)
	at org.testng.TestRunner.privateRun(TestRunner.java:782)
	at org.testng.TestRunner.run(TestRunner.java:632)
	at org.testng.SuiteRunner.runTest(SuiteRunner.java:366)
	at org.testng.SuiteRunner.runSequentially(SuiteRunner.java:361)
	at org.testng.SuiteRunner.privateRun(SuiteRunner.java:319)
	at org.testng.SuiteRunner.run(SuiteRunner.java:268)
	at org.testng.SuiteRunnerWorker.runSuite(SuiteRunnerWorker.java:52)
	at org.testng.SuiteRunnerWorker.run(SuiteRunnerWorker.java:86)
	at org.testng.TestNG.runSuitesSequentially(TestNG.java:1244)
	at org.testng.TestNG.runSuitesLocally(TestNG.java:1169)
	at org.testng.TestNG.run(TestNG.java:1064)
	at org.testng.remote.AbstractRemoteTestNG.run(AbstractRemoteTestNG.java:115)
	at org.testng.remote.RemoteTestNG.initAndRun(RemoteTestNG.java:251)
	at org.testng.remote.RemoteTestNG.main(RemoteTestNG.java:77)
]]>
            </full-stacktrace>
          </exception> <!-- java.lang.AssertionError -->
          <reporter-output>
          </reporter-output>
        </test-method> <!-- class2_Method4 -->
        <test-method status="PASS" signature="class2_Method6()[pri:6, instance:Demo.TestClass3@4f933fd1]" name="class2_Method6" duration-ms="1" started-at="2020-04-01T18:46:01Z" finished-at="2020-04-01T18:46:01Z">
          <reporter-output>
          </reporter-output>
        </test-method> <!-- class2_Method6 -->
      </class> <!-- Demo.TestClass3 -->
      <class name="Demo.TestDemo">
        <test-method status="FAIL" signature="class1_Method2()[pri:0, instance:Demo.TestDemo@735b5592]" name="class1_Method2" duration-ms="12" started-at="2020-04-01T18:46:01Z" finished-at="2020-04-01T18:46:01Z">
          <exception class="java.lang.AssertionError">
            <message>
              <![CDATA[expected [true] but found [false]]]>
            </message>
            <full-stacktrace>
              <![CDATA[java.lang.AssertionError: expected [true] but found [false]
	at org.testng.Assert.fail(Assert.java:94)
	at org.testng.Assert.failNotEquals(Assert.java:513)
	at org.testng.Assert.assertTrue(Assert.java:42)
	at org.testng.Assert.assertTrue(Assert.java:52)
	at Demo.TestDemo.class1_Method2(TestDemo.java:29)
	at sun.reflect.NativeMethodAccessorImpl.invoke0(Native Method)
	at sun.reflect.NativeMethodAccessorImpl.invoke(NativeMethodAccessorImpl.java:62)
	at sun.reflect.DelegatingMethodAccessorImpl.invoke(DelegatingMethodAccessorImpl.java:43)
	at java.lang.reflect.Method.invoke(Method.java:498)
	at org.testng.internal.MethodInvocationHelper.invokeMethod(MethodInvocationHelper.java:86)
	at org.testng.internal.Invoker.invokeMethod(Invoker.java:643)
	at org.testng.internal.Invoker.invokeTestMethod(Invoker.java:820)
	at org.testng.internal.Invoker.invokeTestMethods(Invoker.java:1128)
	at org.testng.internal.TestMethodWorker.invokeTestMethods(TestMethodWorker.java:129)
	at org.testng.internal.TestMethodWorker.run(TestMethodWorker.java:112)
	at org.testng.TestRunner.privateRun(TestRunner.java:782)
	at org.testng.TestRunner.run(TestRunner.java:632)
	at org.testng.SuiteRunner.runTest(SuiteRunner.java:366)
	at org.testng.SuiteRunner.runSequentially(SuiteRunner.java:361)
	at org.testng.SuiteRunner.privateRun(SuiteRunner.java:319)
	at org.testng.SuiteRunner.run(SuiteRunner.java:268)
	at org.testng.SuiteRunnerWorker.runSuite(SuiteRunnerWorker.java:52)
	at org.testng.SuiteRunnerWorker.run(SuiteRunnerWorker.java:86)
	at org.testng.TestNG.runSuitesSequentially(TestNG.java:1244)
	at org.testng.TestNG.runSuitesLocally(TestNG.java:1169)
	at org.testng.TestNG.run(TestNG.java:1064)
	at org.testng.remote.AbstractRemoteTestNG.run(AbstractRemoteTestNG.java:115)
	at org.testng.remote.RemoteTestNG.initAndRun(RemoteTestNG.java:251)
	at org.testng.remote.RemoteTestNG.main(RemoteTestNG.java:77)
]]>
            </full-stacktrace>
          </exception> <!-- java.lang.AssertionError -->
          <reporter-output>
          </reporter-output>
        </test-method> <!-- class1_Method2 -->
        <test-method status="PASS" signature="class1_Method1()[pri:1, instance:Demo.TestDemo@735b5592]" name="class1_Method1" duration-ms="1" started-at="2020-04-01T18:46:01Z" finished-at="2020-04-01T18:46:01Z">
          <reporter-output>
          </reporter-output>
        </test-method> <!-- class1_Method1 -->
        <test-method status="PASS" signature="class1_Method3()[pri:0, instance:Demo.TestDemo@735b5592]" name="class1_Method3" duration-ms="2" started-at="2020-04-01T18:46:01Z" depends-on-methods="Demo.TestDemo.class1_Method1" finished-at="2020-04-01T18:46:01Z">
          <reporter-output>
            <line>
              <![CDATA[[Info] : Test Case is Skiped ]]>
            </line>
          </reporter-output>
        </test-method> <!-- class1_Method3 -->
      </class> <!-- Demo.TestDemo -->
      <class name="Demo.TestClass4">
        <test-method status="PASS" signature="class2_Method5()[pri:0, instance:Demo.TestClass4@548a9f61]" name="class2_Method5" duration-ms="0" started-at="2020-04-01T18:46:01Z" finished-at="2020-04-01T18:46:01Z">
          <reporter-output>
          </reporter-output>
        </test-method> <!-- class2_Method5 -->
        <test-method status="PASS" signature="class2_Method1()[pri:1, instance:Demo.TestClass4@548a9f61]" name="class2_Method1" duration-ms="2" started-at="2020-04-01T18:46:01Z" finished-at="2020-04-01T18:46:01Z">
          <reporter-output>
          </reporter-output>
        </test-method> <!-- class2_Method1 -->
        <test-method status="PASS" signature="class2_Method2()[pri:2, instance:Demo.TestClass4@548a9f61]" name="class2_Method2" duration-ms="1" started-at="2020-04-01T18:46:01Z" finished-at="2020-04-01T18:46:01Z">
          <reporter-output>
          </reporter-output>
        </test-method> <!-- class2_Method2 -->
        <test-method status="FAIL" signature="class2_Method3()[pri:3, instance:Demo.TestClass4@548a9f61]" name="class2_Method3" duration-ms="1" started-at="2020-04-01T18:46:01Z" finished-at="2020-04-01T18:46:01Z">
          <exception class="java.lang.AssertionError">
            <message>
              <![CDATA[expected [true] but found [false]]]>
            </message>
            <full-stacktrace>
              <![CDATA[java.lang.AssertionError: expected [true] but found [false]
	at org.testng.Assert.fail(Assert.java:94)
	at org.testng.Assert.failNotEquals(Assert.java:513)
	at org.testng.Assert.assertTrue(Assert.java:42)
	at org.testng.Assert.assertTrue(Assert.java:52)
	at Demo.TestClass4.class2_Method3(TestClass4.java:22)
	at sun.reflect.NativeMethodAccessorImpl.invoke0(Native Method)
	at sun.reflect.NativeMethodAccessorImpl.invoke(NativeMethodAccessorImpl.java:62)
	at sun.reflect.DelegatingMethodAccessorImpl.invoke(DelegatingMethodAccessorImpl.java:43)
	at java.lang.reflect.Method.invoke(Method.java:498)
	at org.testng.internal.MethodInvocationHelper.invokeMethod(MethodInvocationHelper.java:86)
	at org.testng.internal.Invoker.invokeMethod(Invoker.java:643)
	at org.testng.internal.Invoker.invokeTestMethod(Invoker.java:820)
	at org.testng.internal.Invoker.invokeTestMethods(Invoker.java:1128)
	at org.testng.internal.TestMethodWorker.invokeTestMethods(TestMethodWorker.java:129)
	at org.testng.internal.TestMethodWorker.run(TestMethodWorker.java:112)
	at org.testng.TestRunner.privateRun(TestRunner.java:782)
	at org.testng.TestRunner.run(TestRunner.java:632)
	at org.testng.SuiteRunner.runTest(SuiteRunner.java:366)
	at org.testng.SuiteRunner.runSequentially(SuiteRunner.java:361)
	at org.testng.SuiteRunner.privateRun(SuiteRunner.java:319)
	at org.testng.SuiteRunner.run(SuiteRunner.java:268)
	at org.testng.SuiteRunnerWorker.runSuite(SuiteRunnerWorker.java:52)
	at org.testng.SuiteRunnerWorker.run(SuiteRunnerWorker.java:86)
	at org.testng.TestNG.runSuitesSequentially(TestNG.java:1244)
	at org.testng.TestNG.runSuitesLocally(TestNG.java:1169)
	at org.testng.TestNG.run(TestNG.java:1064)
	at org.testng.remote.AbstractRemoteTestNG.run(AbstractRemoteTestNG.java:115)
	at org.testng.remote.RemoteTestNG.initAndRun(RemoteTestNG.java:251)
	at org.testng.remote.RemoteTestNG.main(RemoteTestNG.java:77)
]]>
            </full-stacktrace>
          </exception> <!-- java.lang.AssertionError -->
          <reporter-output>
          </reporter-output>
        </test-method> <!-- class2_Method3 -->
        <test-method status="FAIL" signature="class2_Method4()[pri:4, instance:Demo.TestClass4@548a9f61]" name="class2_Method4" duration-ms="1" started-at="2020-04-01T18:46:01Z" finished-at="2020-04-01T18:46:01Z">
          <exception class="java.lang.AssertionError">
            <message>
              <![CDATA[expected [true] but found [false]]]>
            </message>
            <full-stacktrace>
              <![CDATA[java.lang.AssertionError: expected [true] but found [false]
	at org.testng.Assert.fail(Assert.java:94)
	at org.testng.Assert.failNotEquals(Assert.java:513)
	at org.testng.Assert.assertTrue(Assert.java:42)
	at org.testng.Assert.assertTrue(Assert.java:52)
	at Demo.TestClass4.class2_Method4(TestClass4.java:28)
	at sun.reflect.NativeMethodAccessorImpl.invoke0(Native Method)
	at sun.reflect.NativeMethodAccessorImpl.invoke(NativeMethodAccessorImpl.java:62)
	at sun.reflect.DelegatingMethodAccessorImpl.invoke(DelegatingMethodAccessorImpl.java:43)
	at java.lang.reflect.Method.invoke(Method.java:498)
	at org.testng.internal.MethodInvocationHelper.invokeMethod(MethodInvocationHelper.java:86)
	at org.testng.internal.Invoker.invokeMethod(Invoker.java:643)
	at org.testng.internal.Invoker.invokeTestMethod(Invoker.java:820)
	at org.testng.internal.Invoker.invokeTestMethods(Invoker.java:1128)
	at org.testng.internal.TestMethodWorker.invokeTestMethods(TestMethodWorker.java:129)
	at org.testng.internal.TestMethodWorker.run(TestMethodWorker.java:112)
	at org.testng.TestRunner.privateRun(TestRunner.java:782)
	at org.testng.TestRunner.run(TestRunner.java:632)
	at org.testng.SuiteRunner.runTest(SuiteRunner.java:366)
	at org.testng.SuiteRunner.runSequentially(SuiteRunner.java:361)
	at org.testng.SuiteRunner.privateRun(SuiteRunner.java:319)
	at org.testng.SuiteRunner.run(SuiteRunner.java:268)
	at org.testng.SuiteRunnerWorker.runSuite(SuiteRunnerWorker.java:52)
	at org.testng.SuiteRunnerWorker.run(SuiteRunnerWorker.java:86)
	at org.testng.TestNG.runSuitesSequentially(TestNG.java:1244)
	at org.testng.TestNG.runSuitesLocally(TestNG.java:1169)
	at org.testng.TestNG.run(TestNG.java:1064)
	at org.testng.remote.AbstractRemoteTestNG.run(AbstractRemoteTestNG.java:115)
	at org.testng.remote.RemoteTestNG.initAndRun(RemoteTestNG.java:251)
	at org.testng.remote.RemoteTestNG.main(RemoteTestNG.java:77)
]]>
            </full-stacktrace>
          </exception> <!-- java.lang.AssertionError -->
          <reporter-output>
          </reporter-output>
        </test-method> <!-- class2_Method4 -->
        <test-method status="PASS" signature="class2_Method6()[pri:6, instance:Demo.TestClass4@548a9f61]" name="class2_Method6" duration-ms="1" started-at="2020-04-01T18:46:01Z" finished-at="2020-04-01T18:46:01Z">
          <reporter-output>
          </reporter-output>
        </test-method> <!-- class2_Method6 -->
      </class> <!-- Demo.TestClass4 -->
      <class name="Demo.TestClass1">
        <test-method status="PASS" signature="class2_Method5()[pri:0, instance:Demo.TestClass1@7dc7cbad]" name="class2_Method5" duration-ms="2" started-at="2020-04-01T18:46:01Z" finished-at="2020-04-01T18:46:01Z">
          <reporter-output>
          </reporter-output>
        </test-method> <!-- class2_Method5 -->
        <test-method status="PASS" signature="class2_Method1()[pri:1, instance:Demo.TestClass1@7dc7cbad]" name="class2_Method1" duration-ms="1" started-at="2020-04-01T18:46:01Z" finished-at="2020-04-01T18:46:01Z">
          <reporter-output>
          </reporter-output>
        </test-method> <!-- class2_Method1 -->
        <test-method status="PASS" signature="class2_Method2()[pri:2, instance:Demo.TestClass1@7dc7cbad]" name="class2_Method2" duration-ms="0" started-at="2020-04-01T18:46:01Z" finished-at="2020-04-01T18:46:01Z">
          <reporter-output>
          </reporter-output>
        </test-method> <!-- class2_Method2 -->
        <test-method status="PASS" signature="class2_Method3()[pri:3, instance:Demo.TestClass1@7dc7cbad]" name="class2_Method3" duration-ms="1" started-at="2020-04-01T18:46:01Z" finished-at="2020-04-01T18:46:01Z">
          <reporter-output>
          </reporter-output>
        </test-method> <!-- class2_Method3 -->
        <test-method status="FAIL" signature="class2_Method4()[pri:4, instance:Demo.TestClass1@7dc7cbad]" name="class2_Method4" duration-ms="1" started-at="2020-04-01T18:46:01Z" finished-at="2020-04-01T18:46:01Z">
          <exception class="java.lang.AssertionError">
            <message>
              <![CDATA[expected [true] but found [false]]]>
            </message>
            <full-stacktrace>
              <![CDATA[java.lang.AssertionError: expected [true] but found [false]
	at org.testng.Assert.fail(Assert.java:94)
	at org.testng.Assert.failNotEquals(Assert.java:513)
	at org.testng.Assert.assertTrue(Assert.java:42)
	at org.testng.Assert.assertTrue(Assert.java:52)
	at Demo.TestClass1.class2_Method4(TestClass1.java:28)
	at sun.reflect.NativeMethodAccessorImpl.invoke0(Native Method)
	at sun.reflect.NativeMethodAccessorImpl.invoke(NativeMethodAccessorImpl.java:62)
	at sun.reflect.DelegatingMethodAccessorImpl.invoke(DelegatingMethodAccessorImpl.java:43)
	at java.lang.reflect.Method.invoke(Method.java:498)
	at org.testng.internal.MethodInvocationHelper.invokeMethod(MethodInvocationHelper.java:86)
	at org.testng.internal.Invoker.invokeMethod(Invoker.java:643)
	at org.testng.internal.Invoker.invokeTestMethod(Invoker.java:820)
	at org.testng.internal.Invoker.invokeTestMethods(Invoker.java:1128)
	at org.testng.internal.TestMethodWorker.invokeTestMethods(TestMethodWorker.java:129)
	at org.testng.internal.TestMethodWorker.run(TestMethodWorker.java:112)
	at org.testng.TestRunner.privateRun(TestRunner.java:782)
	at org.testng.TestRunner.run(TestRunner.java:632)
	at org.testng.SuiteRunner.runTest(SuiteRunner.java:366)
	at org.testng.SuiteRunner.runSequentially(SuiteRunner.java:361)
	at org.testng.SuiteRunner.privateRun(SuiteRunner.java:319)
	at org.testng.SuiteRunner.run(SuiteRunner.java:268)
	at org.testng.SuiteRunnerWorker.runSuite(SuiteRunnerWorker.java:52)
	at org.testng.SuiteRunnerWorker.run(SuiteRunnerWorker.java:86)
	at org.testng.TestNG.runSuitesSequentially(TestNG.java:1244)
	at org.testng.TestNG.runSuitesLocally(TestNG.java:1169)
	at org.testng.TestNG.run(TestNG.java:1064)
	at org.testng.remote.AbstractRemoteTestNG.run(AbstractRemoteTestNG.java:115)
	at org.testng.remote.RemoteTestNG.initAndRun(RemoteTestNG.java:251)
	at org.testng.remote.RemoteTestNG.main(RemoteTestNG.java:77)
]]>
            </full-stacktrace>
          </exception> <!-- java.lang.AssertionError -->
          <reporter-output>
          </reporter-output>
        </test-method> <!-- class2_Method4 -->
        <test-method status="PASS" signature="class2_Method6()[pri:6, instance:Demo.TestClass1@7dc7cbad]" name="class2_Method6" duration-ms="1" started-at="2020-04-01T18:46:01Z" finished-at="2020-04-01T18:46:01Z">
          <reporter-output>
          </reporter-output>
        </test-method> <!-- class2_Method6 -->
      </class> <!-- Demo.TestClass1 -->
      <class name="Demo.TestClass2">
        <test-method status="PASS" signature="class2_Method5()[pri:0, instance:Demo.TestClass2@d2cc05a]" name="class2_Method5" duration-ms="1" started-at="2020-04-01T18:46:01Z" finished-at="2020-04-01T18:46:01Z">
          <reporter-output>
          </reporter-output>
        </test-method> <!-- class2_Method5 -->
        <test-method status="PASS" signature="class2_Method1()[pri:1, instance:Demo.TestClass2@d2cc05a]" name="class2_Method1" duration-ms="1" started-at="2020-04-01T18:46:01Z" finished-at="2020-04-01T18:46:01Z">
          <reporter-output>
          </reporter-output>
        </test-method> <!-- class2_Method1 -->
        <test-method status="PASS" signature="class2_Method2()[pri:2, instance:Demo.TestClass2@d2cc05a]" name="class2_Method2" duration-ms="0" started-at="2020-04-01T18:46:01Z" finished-at="2020-04-01T18:46:01Z">
          <reporter-output>
          </reporter-output>
        </test-method> <!-- class2_Method2 -->
        <test-method status="PASS" signature="class2_Method3()[pri:3, instance:Demo.TestClass2@d2cc05a]" name="class2_Method3" duration-ms="1" started-at="2020-04-01T18:46:01Z" finished-at="2020-04-01T18:46:01Z">
          <reporter-output>
          </reporter-output>
        </test-method> <!-- class2_Method3 -->
        <test-method status="FAIL" signature="class2_Method4()[pri:4, instance:Demo.TestClass2@d2cc05a]" name="class2_Method4" duration-ms="1" started-at="2020-04-01T18:46:01Z" finished-at="2020-04-01T18:46:01Z">
          <exception class="java.lang.AssertionError">
            <message>
              <![CDATA[expected [true] but found [false]]]>
            </message>
            <full-stacktrace>
              <![CDATA[java.lang.AssertionError: expected [true] but found [false]
	at org.testng.Assert.fail(Assert.java:94)
	at org.testng.Assert.failNotEquals(Assert.java:513)
	at org.testng.Assert.assertTrue(Assert.java:42)
	at org.testng.Assert.assertTrue(Assert.java:52)
	at Demo.TestClass2.class2_Method4(TestClass2.java:28)
	at sun.reflect.NativeMethodAccessorImpl.invoke0(Native Method)
	at sun.reflect.NativeMethodAccessorImpl.invoke(NativeMethodAccessorImpl.java:62)
	at sun.reflect.DelegatingMethodAccessorImpl.invoke(DelegatingMethodAccessorImpl.java:43)
	at java.lang.reflect.Method.invoke(Method.java:498)
	at org.testng.internal.MethodInvocationHelper.invokeMethod(MethodInvocationHelper.java:86)
	at org.testng.internal.Invoker.invokeMethod(Invoker.java:643)
	at org.testng.internal.Invoker.invokeTestMethod(Invoker.java:820)
	at org.testng.internal.Invoker.invokeTestMethods(Invoker.java:1128)
	at org.testng.internal.TestMethodWorker.invokeTestMethods(TestMethodWorker.java:129)
	at org.testng.internal.TestMethodWorker.run(TestMethodWorker.java:112)
	at org.testng.TestRunner.privateRun(TestRunner.java:782)
	at org.testng.TestRunner.run(TestRunner.java:632)
	at org.testng.SuiteRunner.runTest(SuiteRunner.java:366)
	at org.testng.SuiteRunner.runSequentially(SuiteRunner.java:361)
	at org.testng.SuiteRunner.privateRun(SuiteRunner.java:319)
	at org.testng.SuiteRunner.run(SuiteRunner.java:268)
	at org.testng.SuiteRunnerWorker.runSuite(SuiteRunnerWorker.java:52)
	at org.testng.SuiteRunnerWorker.run(SuiteRunnerWorker.java:86)
	at org.testng.TestNG.runSuitesSequentially(TestNG.java:1244)
	at org.testng.TestNG.runSuitesLocally(TestNG.java:1169)
	at org.testng.TestNG.run(TestNG.java:1064)
	at org.testng.remote.AbstractRemoteTestNG.run(AbstractRemoteTestNG.java:115)
	at org.testng.remote.RemoteTestNG.initAndRun(RemoteTestNG.java:251)
	at org.testng.remote.RemoteTestNG.main(RemoteTestNG.java:77)
]]>
            </full-stacktrace>
          </exception> <!-- java.lang.AssertionError -->
          <reporter-output>
          </reporter-output>
        </test-method> <!-- class2_Method4 -->
        <test-method status="PASS" signature="class2_Method6()[pri:6, instance:Demo.TestClass2@d2cc05a]" name="class2_Method6" duration-ms="1" started-at="2020-04-01T18:46:01Z" finished-at="2020-04-01T18:46:01Z">
          <reporter-output>
          </reporter-output>
        </test-method> <!-- class2_Method6 -->
      </class> <!-- Demo.TestClass2 -->
    </test> <!-- Tests -->
  </suite> <!-- SuiteNameHere -->
</testng-results>
